Workbook

Sheet Read Me
B2: Bond Portfolio Model
B3: version 2.2
B5: Objective
C6: This model is built for Goldman Sachs, with the objective to look across various fixed income asset classes (munis, corporates, treasuries, etc.) and come up with an optimized, laddered portfolio based on client’s federal and state tax rates.
C7: And then optimize over time based on changes in the market, clients cost basis, short term versus long term tax implications.
B9: Investor Input
C10: The Investor Input tab is where the client or the investor specifies some of the basic details like their state of residence, tax bracket, amount to invest, and investment horizon
B12: Bond Portfolio Scenarios - High Yield Scenario, Secure Bonds Scenario, and Stable Income Scenario
C13: Each scenario tab is built to present a list of bonds curated and personalized based on client's inputs on the Investor Input tab.
C14: The client can go into each tab and go down the list to pick the number of bonds to purchase for each CUSIP. The cells meant to be updated are shaded yellow (column M).
C15: Note that the purchase quantity entered in column M cannot be less than the minimum quantity specified within parantheses in column L. The field should be left blank to exclude the bond from purchase.
C16: Also note that the total price at the bottom of the list cannot exceed the amount entered in the Investor Input tab. If this happens the cell will turn red to indicate the error.
B18: YTM Analysis
C19: The YTM Analysis tab presents a comprehensive Pre-Tax /After-Tax Yield to Maturity comparison for each scenario. Toggle between Pre-/After-Tax options from the dropdown to compare the YTM changes for each portfolio.
C20: The table at the bottom of the tab lists the Y/Y yields while the average yield and average credit rating of each portfolio is listed on the bottom right.
B22: Cash Flow Analysis
C23: The Cash Flow Analysis is meant to present a comparison of coupon payments by month for each scenario. This provides the client with an option to take a laddered approach when picking the bonds for their portfolio.
C24: The client can adjust their portfolio on the scenario tabs and then go to the Cash Flow Analysis tab to compare the month over month income in any given year.
C25: Similar to the YTM Analysis tab, client can toggle between Pre-/After-Tax options from the dropdown to compare the YTM changes for each portfolio.
B27: Master Bond List (hidden)
C28: This is the master list of all the relevant bonds.
B30: Misc Lists (hidden)
C31: List of user input validation

Sheet Investor Input
B2: Investor Input
B3: State of Residence: | C3: New Jersey | D3: =VLOOKUP('Investor Input'!C3,'Misc Lists'!A2:B51,2,TRUE) -> NJ
B4: Federal Tax Bracket: | C4: 0.37
B5: State Tax Bracket: | C5: 0.09
B6: Amount to Invest ($) | C6: 1000000
B7: Investment Horizon (Years): | C7: 5

Sheet High Yield Scenario
A1: {=MID(CELL("filename",A1),FIND("]",CELL("filename",A1))+1,255)} -> High Yield Scenario
B2: General Bond Information | M2: Purchase Information | V2: Valuation on Maturity | Y2: Yearly Cash Flow Information | AC2: Rating Info
B3: CUSIP | C3: State | D3: Description | E3: Type | F3: Cpn | G3: Maturity Date | H3: Mdy | I3: S&P | J3: Price | K3: YTM | L3: Qty (Min) | M3: Purchase Qty | N3: Total Price | O3: Portfolio Pct | P3: Annual Coupon | Q3: Purchase Date | R3: Yrs to Maturity | S3: Duration Yrs | T3: YTM At Buy | U3: After-Tax YTM | V3: Price | W3: Interest Earned | X3: Total Return | Y3: 1st Coupon Mth | Z3: 2nd Coupon Month | AA3: Coupon Amt | AB3: After-Tax Coupon Amt | AC3: Mdy Rating | AD3: Mdy Score | AE3: S&P Rating | AF3: S&P Score
B4: {=_xlfn.TAKE(_xlfn._xlws.SORT(_xlfn._xlws.FILTER(_xlfn._xlws.FILTER(Master_Bond_List[], ('Investor Input'!C6 >= IFERROR(VALUE(MID(Master_Bond_List[Quantity Ask(min)], FIND("(", Master_Bond_List[Quantity Ask(min)]) + 1, LEN(Master_Bond_List[Quantity Ask(min)]) - FIND("(", Master_Bond_List[Quantity Ask(min)])-1)), 1)*1000)*((Master_Bond_List[Maturity Date]-TODAY()) < 'Investor Input'!C7*365)*(Master_Bond_List[Type] = "Muni")*(Master_Bond_List[State]='Investor Input'!D3) + ('Investor Input'!C6 >= IFERROR(VALUE(MID(Master_Bond_List[Quantity Ask(min)], FIND("(", Master_Bond_List[Quantity Ask(min)]) + 1, LEN(Master_Bond_List[Quantity Ask(min)]) - FIND("(", Master_Bond_List[Quantity Ask(min)])-1)), 1)*1000)*((Master_Bond_List[Maturity Date]-TODAY()) < 'Investor Input'!C7*365)*(Master_Bond_List[Type] = "Corp")), {1,1,1,1,1,1,0,1,1,0,1,0,0,1,0,0,1,0}), {4,10}, {1,-1}),500)} -> 06745NUM6 | C4: N/A | D4: BARCLAYS BANK PLC SER A MTN 6.25000% 11/03/2028 | E4: Corp | F4: 6.25 | G4: 47060 | H4: A1 | I4: A+ | J4: 100.888 | K4: 5.972 | L4: 1(1) | N4: =IF(AND(M4<>"", M4<>0), IF(L4 <> "N/A", IF(M4>=VALUE(LEFT(L4, FIND("(", L4)-1)), J4*10*M4, 1000*M4), 1000*M4), "") | O4: =IF(AND(M4<>"",M4<>0),N4/$N$505, "") | P4: =IF(AND(M4<>"", M4<>0), F4*1000/100, "") | Q4: =IF(AND(M4<>"", M4<>0), NOW(), "") | R4: =IF(AND(M4<>"", M4<>0), ROUND((G4 - Q4)/365, 0), "") | S4: =IF(AND(M4<>"",M4<>0),MDURATION(Q4,G4,F4/100,K4/100,2), "") | T4: =IF(AND(M4<>"",M4<>0),YIELD(Q4,G4,F4/100,N4/(M4*10),100,2),"") | U4: =IF(AND(M4<>"",M4<>0), IF(E4 = "Muni", T4, IF(E4="Corp", T4*(1 -'Investor Input'!$C$4-'Investor Input'!$C$5), T4*(1 -'Investor Input'!$C$4))), T4) | V4: =IF(AND(M4<>"",M4<>0),(FV(K4/(2*100),(G4-Q4)*2/365, F4*1000/(2*100), -N4/M4))*M4, "") | W4: =IF(AND(M4<>"",M4<>0),V4-N4,"") | X4: =IF(AND(M4<>"",M4<>0),W4/N4,"") | Y4: =IF(AND(M4<>"", M4<>0), MONTH(G4), "") | Z4: =IF(AND(M4<>"", M4<>0), MONTH(EDATE(G4, 6)), "") | AA4: =IF(AND(M4<>"", M4<>0), F4*1000*M4/(100*2), "") | AB4: =IF(AND(AA4<>"",AA4<>0), IF(E4="Muni", AA4, IF(E4 = "Corp", (1-'Investor Input'!$C$4-'Investor Input'!$C$5)*AA4, (1-'Investor Input'!$C$4)*AA4)), AA4) | AC4: =IF(AND(M4<>"", M4<>0), H4, "") | AD4: =IF(AND(M4<>"", M4<>0), N4/$N$505*MATCH(AC4,'Misc Lists'!$K$2:$K$25,0), "") | AE4: =IF(AND(M4<>"", M4<>0), I4, "") | AF4: =IF(AND(M4<>"", M4<>0), N4/$N$505*MATCH(AE4,'Misc Lists'!$L$2:$L$25,0), "")
B5: 06055JFF1 | C5: N/A | D5: BANK AMERICA CORP SER P MTN 5.50000% 07/23/2029 | E5: Corp | F5: 5.5 | G5: 47322 | H5: A1 | I5: A- | J5: 100.407 | K5: 5.392 | L5: 3(3) | N5: =IF(AND(M5<>"", M5<>0), IF(L5 <> "N/A", IF(M5>=VALUE(LEFT(L5, FIND("(", L5)-1)), J5*10*M5, 1000*M5), 1000*M5), "") | O5: =IF(AND(M5<>"",M5<>0),N5/$N$505, "") | P5: =IF(AND(M5<>"", M5<>0), F5*1000/100, "") | Q5: =IF(AND(M5<>"", M5<>0), NOW(), "") | R5: =IF(AND(M5<>"", M5<>0), ROUND((G5 - Q5)/365, 0), "") | S5: =IF(AND(M5<>"",M5<>0),MDURATION(Q5,G5,F5/100,K5/100,2), "") | T5: =IF(AND(M5<>"",M5<>0),YIELD(Q5,G5,F5/100,N5/(M5*10),100,2),"") | U5: =IF(AND(M5<>"",M5<>0), IF(E5 = "Muni", T5, IF(E5="Corp", T5*(1 -'Investor Input'!$C$4-'Investor Input'!$C$5), T5*(1 -'Investor Input'!$C$4))), T5) | V5: =IF(AND(M5<>"",M5<>0),(FV(K5/(2*100),(G5-Q5)*2/365, F5*1000/(2*100), -N5/M5))*M5, "") | W5: =IF(AND(M5<>"",M5<>0),V5-N5,"") | X5: =IF(AND(M5<>"",M5<>0),W5/N5,"") | Y5: =IF(AND(M5<>"", M5<>0), MONTH(G5), "") | Z5: =IF(AND(M5<>"", M5<>0), MONTH(EDATE(G5, 6)), "") | AA5: =IF(AND(M5<>"", M5<>0), F5*1000*M5/(100*2), "") | AB5: =IF(AND(AA5<>"",AA5<>0), IF(E5="Muni", AA5, IF(E5 = "Corp", (1-'Investor Input'!$C$4-'Investor Input'!$C$5)*AA5, (1-'Investor Input'!$C$4)*AA5)), AA5) | AC5: =IF(AND(M5<>"", M5<>0), H5, "") | AD5: =IF(AND(M5<>"", M5<>0), N5/$N$505*MATCH(AC5,'Misc Lists'!$K$2:$K$25,0), "") | AE5: =IF(AND(M5<>"", M5<>0), I5, "") | AF5: =IF(AND(M5<>"", M5<>0), N5/$N$505*MATCH(AE5,'Misc Lists'!$L$2:$L$25,0), "")
B6: 89114XD67 | C6: N/A | D6: TORONTO DOMINION BK ONT SER D MTN 5.30000% 01/03/2028 | E6: Corp | F6: 5.3 | G6: 46755 | H6: A2 | I6: A- | J6: 99.937 | K6: 5.324 | L6: 15(1) | M6: 15 | N6: =IF(AND(M6<>"", M6<>0), IF(L6 <> "N/A", IF(M6>=VALUE(LEFT(L6, FIND("(", L6)-1)), J6*10*M6, 1000*M6), 1000*M6), "") -> 14990.55 | O6: =IF(AND(M6<>"",M6<>0),N6/$N$505, "") -> 0.014989935 | P6: =IF(AND(M6<>"", M6<>0), F6*1000/100, "") -> 53 | Q6: =IF(AND(M6<>"", M6<>0), NOW(), "") -> 45791.491 | R6: =IF(AND(M6<>"", M6<>0), ROUND((G6 - Q6)/365, 0), "") -> 3 | S6: =IF(AND(M6<>"",M6<>0),MDURATION(Q6,G6,F6/100,K6/100,2), "") -> 2.3854552 | T6: =IF(AND(M6<>"",M6<>0),YIELD(Q6,G6,F6/100,N6/(M6*10),100,2),"") -> 0.053230872 | U6: =IF(AND(M6<>"",M6<>0), IF(E6 = "Muni", T6, IF(E6="Corp", T6*(1 -'Investor Input'!$C$4-'Investor Input'!$C$5), T6*(1 -'Investor Input'!$C$4))), T6) -> 0.028744671 | V6: =IF(AND(M6<>"",M6<>0),(FV(K6/(2*100),(G6-Q6)*2/365, F6*1000/(2*100), -N6/M6))*M6, "") -> 14999.204 | W6: =IF(AND(M6<>"",M6<>0),V6-N6,"") -> 8.6543994 | X6: =IF(AND(M6<>"",M6<>0),W6/N6,"") -> 0.00057732367 | Y6: =IF(AND(M6<>"", M6<>0), MONTH(G6), "") -> 1 | Z6: =IF(AND(M6<>"", M6<>0), MONTH(EDATE(G6, 6)), "") -> 7 | AA6: =IF(AND(M6<>"", M6<>0), F6*1000*M6/(100*2), "") -> 397.5 | AB6: =IF(AND(AA6<>"",AA6<>0), IF(E6="Muni", AA6, IF(E6 = "Corp", (1-'Investor Input'!$C$4-'Investor Input'!$C$5)*AA6, (1-'Investor Input'!$C$4)*AA6)), AA6) -> 214.65 | AC6: =IF(AND(M6<>"", M6<>0), H6, "") -> A2 | AD6: =IF(AND(M6<>"", M6<>0), N6/$N$505*MATCH(AC6,'Misc Lists'!$K$2:$K$25,0), "") -> 0.10492954 | AE6: =IF(AND(M6<>"", M6<>0), I6, "") -> A- | AF6: =IF(AND(M6<>"", M6<>0), N6/$N$505*MATCH(AE6,'Misc Lists'!$L$2:$L$25,0), "") -> 0.11991948
B7: 89114XDN0 | C7: N/A | D7: TORONTO DOMINION BK ONT SER D MTN 5.25000% 01/30/2029 | E7: Corp | F7: 5.25 | G7: 47148 | H7: A2 | I7: A- | J7: 99.995 | K7: 5.251 | L7: 41(25) | N7: =IF(AND(M7<>"", M7<>0), IF(L7 <> "N/A", IF(M7>=VALUE(LEFT(L7, FIND("(", L7)-1)), J7*10*M7, 1000*M7), 1000*M7), "") | O7: =IF(AND(M7<>"",M7<>0),N7/$N$505, "") | P7: =IF(AND(M7<>"", M7<>0), F7*1000/100, "") | Q7: =IF(AND(M7<>"", M7<>0), NOW(), "") | R7: =IF(AND(M7<>"", M7<>0), ROUND((G7 - Q7)/365, 0), "") | S7: =IF(AND(M7<>"",M7<>0),MDURATION(Q7,G7,F7/100,K7/100,2), "") | T7: =IF(AND(M7<>"",M7<>0),YIELD(Q7,G7,F7/100,N7/(M7*10),100,2),"") | U7: =IF(AND(M7<>"",M7<>0), IF(E7 = "Muni", T7, IF(E7="Corp", T7*(1 -'Investor Input'!$C$4-'Investor Input'!$C$5), T7*(1 -'Investor Input'!$C$4))), T7) | V7: =IF(AND(M7<>"",M7<>0),(FV(K7/(2*100),(G7-Q7)*2/365, F7*1000/(2*100), -N7/M7))*M7, "") | W7: =IF(AND(M7<>"",M7<>0),V7-N7,"") | X7: =IF(AND(M7<>"",M7<>0),W7/N7,"") | Y7: =IF(AND(M7<>"", M7<>0), MONTH(G7), "") | Z7: =IF(AND(M7<>"", M7<>0), MONTH(EDATE(G7, 6)), "") | AA7: =IF(AND(M7<>"", M7<>0), F7*1000*M7/(100*2), "") | AB7: =IF(AND(AA7<>"",AA7<>0), IF(E7="Muni", AA7, IF(E7 = "Corp", (1-'Investor Input'!$C$4-'Investor Input'!$C$5)*AA7, (1-'Investor Input'!$C$4)*AA7)), AA7) | AC7: =IF(AND(M7<>"", M7<>0), H7, "") | AD7: =IF(AND(M7<>"", M7<>0), N7/$N$505*MATCH(AC7,'Misc Lists'!$K$2:$K$25,0), "") | AE7: =IF(AND(M7<>"", M7<>0), I7, "") | AF7: =IF(AND(M7<>"", M7<>0), N7/$N$505*MATCH(AE7,'Misc Lists'!$L$2:$L$25,0), "")
B8: 00828EEX3 | C8: N/A | D8: AFRICAN DEV BK MTN SB NTS BE NOTE 5.50000% 11/10/2028 | E8: Corp | F8: 5.5 | G8: 47067 | H8: AAA | I8: AAA | J8: 100.918 | K8: 5.209 | L8: 316(100) | N8: =IF(AND(M8<>"", M8<>0), IF(L8 <> "N/A", IF(M8>=VALUE(LEFT(L8, FIND("(", L8)-1)), J8*10*M8, 1000*M8), 1000*M8), "") | O8: =IF(AND(M8<>"",M8<>0),N8/$N$505, "") | P8: =IF(AND(M8<>"", M8<>0), F8*1000/100, "") | Q8: =IF(AND(M8<>"", M8<>0), NOW(), "") | R8: =IF(AND(M8<>"", M8<>0), ROUND((G8 - Q8)/365, 0), "") | S8: =IF(AND(M8<>"",M8<>0),MDURATION(Q8,G8,F8/100,K8/100,2), "") | T8: =IF(AND(M8<>"",M8<>0),YIELD(Q8,G8,F8/100,N8/(M8*10),100,2),"") | U8: =IF(AND(M8<>"",M8<>0), IF(E8 = "Muni", T8, IF(E8="Corp", T8*(1 -'Investor Input'!$C$4-'Investor Input'!$C$5), T8*(1 -'Investor Input'!$C$4))), T8) | V8: =IF(AND(M8<>"",M8<>0),(FV(K8/(2*100),(G8-Q8)*2/365, F8*1000/(2*100), -N8/M8))*M8, "") | W8: =IF(AND(M8<>"",M8<>0),V8-N8,"") | X8: =IF(AND(M8<>"",M8<>0),W8/N8,"") | Y8: =IF(AND(M8<>"", M8<>0), MONTH(G8), "") | Z8: =IF(AND(M8<>"", M8<>0), MONTH(EDATE(G8, 6)), "") | AA8: =IF(AND(M8<>"", M8<>0), F8*1000*M8/(100*2), "") | AB8: =IF(AND(AA8<>"",AA8<>0), IF(E8="Muni", AA8, IF(E8 = "Corp", (1-'Investor Input'!$C$4-'Investor Input'!$C$5)*AA8, (1-'Investor Input'!$C$4)*AA8)), AA8) | AC8: =IF(AND(M8<>"", M8<>0), H8, "") | AD8: =IF(AND(M8<>"", M8<>0), N8/$N$505*MATCH(AC8,'Misc Lists'!$K$2:$K$25,0), "") | AE8: =IF(AND(M8<>"", M8<>0), I8, "") | AF8: =IF(AND(M8<>"", M8<>0), N8/$N$505*MATCH(AE8,'Misc Lists'!$L$2:$L$25,0), "")
B9: 22552XXR9 | C9: N/A | D9: UBS AG LONDON BRANCHMTN 2.00000% 10/29/2029 ISIN #US22552XXR96 | E9: Corp | F9: 2 | G9: 47420 | H9: AA2 | I9: -- | J9: 86.968 | K9: 5.203 | L9: 75(5) | M9: 100 | N9: =IF(AND(M9<>"", M9<>0), IF(L9 <> "N/A", IF(M9>=VALUE(LEFT(L9, FIND("(", L9)-1)), J9*10*M9, 1000*M9), 1000*M9), "") -> 86968 | O9: =IF(AND(M9<>"",M9<>0),N9/$N$505, "") -> 0.08696443 | P9: =IF(AND(M9<>"", M9<>0), F9*1000/100, "") -> 20 | Q9: =IF(AND(M9<>"", M9<>0), NOW(), "") -> 45791.491 | R9: =IF(AND(M9<>"", M9<>0), ROUND((G9 - Q9)/365, 0), "") -> 4 | S9: =IF(AND(M9<>"",M9<>0),MDURATION(Q9,G9,F9/100,K9/100,2), "") -> 4.1605769 | T9: =IF(AND(M9<>"",M9<>0),YIELD(Q9,G9,F9/100,N9/(M9*10),100,2),"") -> 0.053218215 | U9: =IF(AND(M9<>"",M9<>0), IF(E9 = "Muni", T9, IF(E9="Corp", T9*(1 -'Investor Input'!$C$4-'Investor Input'!$C$5), T9*(1 -'Investor Input'!$C$4))), T9) -> 0.028737836 | V9: =IF(AND(M9<>"",M9<>0),(FV(K9/(2*100),(G9-Q9)*2/365, F9*1000/(2*100), -N9/M9))*M9, "") -> 99466.976 | W9: =IF(AND(M9<>"",M9<>0),V9-N9,"") -> 12498.976 | X9: =IF(AND(M9<>"",M9<>0),W9/N9,"") -> 0.14371926 | Y9: =IF(AND(M9<>"", M9<>0), MONTH(G9), "") -> 10 | Z9: =IF(AND(M9<>"", M9<>0), MONTH(EDATE(G9, 6)), "") -> 4 | AA9: =IF(AND(M9<>"", M9<>0), F9*1000*M9/(100*2), "") -> 1000 | AB9: =IF(AND(AA9<>"",AA9<>0), IF(E9="Muni", AA9, IF(E9 = "Corp", (1-'Investor Input'!$C$4-'Investor Input'!$C$5)*AA9, (1-'Investor Input'!$C$4)*AA9)), AA9) -> 540 | AC9: =IF(AND(M9<>"", M9<>0), H9, "") -> AA2 | AD9: =IF(AND(M9<>"", M9<>0), N9/$N$505*MATCH(AC9,'Misc Lists'!$K$2:$K$25,0), "") -> 0.34785772 | AE9: =IF(AND(M9<>"", M9<>0), I9, "") -> -- | AF9: =IF(AND(M9<>"", M9<>0), N9/$N$505*MATCH(AE9,'Misc Lists'!$L$2:$L$25,0), "") -> 2.0001819
B10: 13607XVD6 | C10: N/A | D10: CANADIAN IMPERIAL BKCOMM MTN 5.25000% 01/30/2030 | E10: Corp | F10: 5.25 | G10: 47513 | H10: A2 | I10: A- | J10: 100.379 | K10: 5.16 | L10: 407(1) | N10: =IF(AND(M10<>"", M10<>0), IF(L10 <> "N/A", IF(M10>=VALUE(LEFT(L10, FIND("(", L10)-1)), J10*10*M10, 1000*M10), 1000*M10), "") | O10: =IF(AND(M10<>"",M10<>0),N10/$N$505, "") | P10: =IF(AND(M10<>"", M10<>0), F10*1000/100, "") | Q10: =IF(AND(M10<>"", M10<>0), NOW(), "") | R10: =IF(AND(M10<>"", M10<>0), ROUND((G10 - Q10)/365, 0), "") | S10: =IF(AND(M10<>"",M10<>0),MDURATION(Q10,G10,F10/100,K10/100,2), "") | T10: =IF(AND(M10<>"",M10<>0),YIELD(Q10,G10,F10/100,N10/(M10*10),100,2),"") | U10: =IF(AND(M10<>"",M10<>0), IF(E10 = "Muni", T10, IF(E10="Corp", T10*(1 -'Investor Input'!$C$4-'Investor Input'!$C$5), T10*(1 -'Investor Input'!$C$4))), T10) | V10: =IF(AND(M10<>"",M10<>0),(FV(K10/(2*100),(G10-Q10)*2/365, F10*1000/(2*100), -N10/M10))*M10, "") | W10: =IF(AND(M10<>"",M10<>0),V10-N10,"") | X10: =IF(AND(M10<>"",M10<>0),W10/N10,"") | Y10: =IF(AND(M10<>"", M10<>0), MONTH(G10), "") | Z10: =IF(AND(M10<>"", M10<>0), MONTH(EDATE(G10, 6)), "") | AA10: =IF(AND(M10<>"", M10<>0), F10*1000*M10/(100*2), "") | AB10: =IF(AND(AA10<>"",AA10<>0), IF(E10="Muni", AA10, IF(E10 = "Corp", (1-'Investor Input'!$C$4-'Investor Input'!$C$5)*AA10, (1-'Investor Input'!$C$4)*AA10)), AA10) | AC10: =IF(AND(M10<>"", M10<>0), H10, "") | AD10: =IF(AND(M10<>"", M10<>0), N10/$N$505*MATCH(AC10,'Misc Lists'!$K$2:$K$25,0), "") | AE10: =IF(AND(M10<>"", M10<>0), I10, "") | AF10: =IF(AND(M10<>"", M10<>0), N10/$N$505*MATCH(AE10,'Misc Lists'!$L$2:$L$25,0), "")
B11: 46514Y8A8 | C11: N/A | D11: ISRAEL ST BOND 5.37500% 02/19/2030 | E11: Corp | F11: 5.375 | G11: 47533 | H11: BAA1 | I11: A | J11: 100.958 | K11: 5.152 | L11: 1,000(200) | N11: =IF(AND(M11<>"", M11<>0), IF(L11 <> "N/A", IF(M11>=VALUE(LEFT(L11, FIND("(", L11)-1)), J11*10*M11, 1000*M11), 1000*M11), "") | O11: =IF(AND(M11<>"",M11<>0),N11/$N$505, "") | P11: =IF(AND(M11<>"", M11<>0), F11*1000/100, "") | Q11: =IF(AND(M11<>"", M11<>0), NOW(), "") | R11: =IF(AND(M11<>"", M11<>0), ROUND((G11 - Q11)/365, 0), "") | S11: =IF(AND(M11<>"",M11<>0),MDURATION(Q11,G11,F11/100,K11/100,2), "") | T11: =IF(AND(M11<>"",M11<>0),YIELD(Q11,G11,F11/100,N11/(M11*10),100,2),"") | U11: =IF(AND(M11<>"",M11<>0), IF(E11 = "Muni", T11, IF(E11="Corp", T11*(1 -'Investor Input'!$C$4-'Investor Input'!$C$5), T11*(1 -'Investor Input'!$C$4))), T11) | V11: =IF(AND(M11<>"",M11<>0),(FV(K11/(2*100),(G11-Q11)*2/365, F11*1000/(2*100), -N11/M11))*M11, "") | W11: =IF(AND(M11<>"",M11<>0),V11-N11,"") | X11: =IF(AND(M11<>"",M11<>0),W11/N11,"") | Y11: =IF(AND(M11<>"", M11<>0), MONTH(G11), "") | Z11: =IF(AND(M11<>"", M11<>0), MONTH(EDATE(G11, 6)), "") | AA11: =IF(AND(M11<>"", M11<>0), F11*1000*M11/(100*2), "") | AB11: =IF(AND(AA11<>"",AA11<>0), IF(E11="Muni", AA11, IF(E11 = "Corp", (1-'Investor Input'!$C$4-'Investor Input'!$C$5)*AA11, (1-'Investor Input'!$C$4)*AA11)), AA11) | AC11: =IF(AND(M11<>"", M11<>0), H11, "") | AD11: =IF(AND(M11<>"", M11<>0), N11/$N$505*MATCH(AC11,'Misc Lists'!$K$2:$K$25,0), "") | AE11: =IF(AND(M11<>"", M11<>0), I11, "") | AF11: =IF(AND(M11<>"", M11<>0), N11/$N$505*MATCH(AE11,'Misc Lists'!$L$2:$L$25,0), "")
B12: 25161FKM9 | C12: N/A | D12: DEUTSCHE BK AG SER E NOTE 5.25000% 02/15/2030 | E12: Corp | F12: 5.25 | G12: 47529 | H12: A1 | I12: A | J12: 100.5 | K12: 5.131 | L12: 73(1) | N12: =IF(AND(M12<>"", M12<>0), IF(L12 <> "N/A", IF(M12>=VALUE(LEFT(L12, FIND("(", L12)-1)), J12*10*M12, 1000*M12), 1000*M12), "") | O12: =IF(AND(M12<>"",M12<>0),N12/$N$505, "") | P12: =IF(AND(M12<>"", M12<>0), F12*1000/100, "") | Q12: =IF(AND(M12<>"", M12<>0), NOW(), "") | R12: =IF(AND(M12<>"", M12<>0), ROUND((G12 - Q12)/365, 0), "") | S12: =IF(AND(M12<>"",M12<>0),MDURATION(Q12,G12,F12/100,K12/100,2), "") | T12: =IF(AND(M12<>"",M12<>0),YIELD(Q12,G12,F12/100,N12/(M12*10),100,2),"") | U12: =IF(AND(M12<>"",M12<>0), IF(E12 = "Muni", T12, IF(E12="Corp", T12*(1 -'Investor Input'!$C$4-'Investor Input'!$C$5), T12*(1 -'Investor Input'!$C$4))), T12) | V12: =IF(AND(M12<>"",M12<>0),(FV(K12/(2*100),(G12-Q12)*2/365, F12*1000/(2*100), -N12/M12))*M12, "") | W12: =IF(AND(M12<>"",M12<>0),V12-N12,"") | X12: =IF(AND(M12<>"",M12<>0),W12/N12,"") | Y12: =IF(AND(M12<>"", M12<>0), MONTH(G12), "") | Z12: =IF(AND(M12<>"", M12<>0), MONTH(EDATE(G12, 6)), "") | AA12: =IF(AND(M12<>"", M12<>0), F12*1000*M12/(100*2), "") | AB12: =IF(AND(AA12<>"",AA12<>0), IF(E12="Muni", AA12, IF(E12 = "Corp", (1-'Investor Input'!$C$4-'Investor Input'!$C$5)*AA12, (1-'Investor Input'!$C$4)*AA12)), AA12) | AC12: =IF(AND(M12<>"", M12<>0), H12, "") | AD12: =IF(AND(M12<>"", M12<>0), N12/$N$505*MATCH(AC12,'Misc Lists'!$K$2:$K$25,0), "") | AE12: =IF(AND(M12<>"", M12<>0), I12, "") | AF12: =IF(AND(M12<>"", M12<>0), N12/$N$505*MATCH(AE12,'Misc Lists'!$L$2:$L$25,0), "")
B13: 842400GQ0 | C13: N/A | D13: SOUTHERN CALIF EDISON CO SER 2019A 4.20000% 03/01/2029 BOND CALL MAKE WHOLE | E13: Corp | F13: 4.2 | G13: 47178 | H13: A2 | I13: A- | J13: 96.697 | K13: 5.13 | L13: 200(1) | M13: 200 | N13: =IF(AND(M13<>"", M13<>0), IF(L13 <> "N/A", IF(M13>=VALUE(LEFT(L13, FIND("(", L13)-1)), J13*10*M13, 1000*M13), 1000*M13), "") -> 193394 | O13: =IF(AND(M13<>"",M13<>0),N13/$N$505, "") -> 0.19338606 | P13: =IF(AND(M13<>"", M13<>0), F13*1000/100, "") -> 42 | Q13: =IF(AND(M13<>"", M13<>0), NOW(), "") -> 45791.491 | R13: =IF(AND(M13<>"", M13<>0), ROUND((G13 - Q13)/365, 0), "") -> 4 | S13: =IF(AND(M13<>"",M13<>0),MDURATION(Q13,G13,F13/100,K13/100,2), "") -> 3.4271848 | T13: =IF(AND(M13<>"",M13<>0),YIELD(Q13,G13,F13/100,N13/(M13*10),100,2),"") -> 0.051672327 | U13: =IF(AND(M13<>"",M13<>0), IF(E13 = "Muni", T13, IF(E13="Corp", T13*(1 -'Investor Input'!$C$4-'Investor Input'!$C$5), T13*(1 -'Investor Input'!$C$4))), T13) -> 0.027903057 | V13: =IF(AND(M13<>"",M13<>0),(FV(K13/(2*100),(G13-Q13)*2/365, F13*1000/(2*100), -N13/M13))*M13, "") -> 199685.17 | W13: =IF(AND(M13<>"",M13<>0),V13-N13,"") -> 6291.1727 | X13: =IF(AND(M13<>"",M13<>0),W13/N13,"") -> 0.03253034 | Y13: =IF(AND(M13<>"", M13<>0), MONTH(G13), "") -> 3 | Z13: =IF(AND(M13<>"", M13<>0), MONTH(EDATE(G13, 6)), "") -> 9 | AA13: =IF(AND(M13<>"", M13<>0), F13*1000*M13/(100*2), "") -> 4200 | AB13: =IF(AND(AA13<>"",AA13<>0), IF(E13="Muni", AA13, IF(E13 = "Corp", (1-'Investor Input'!$C$4-'Investor Input'!$C$5)*AA13, (1-'Investor Input'!$C$4)*AA13)), AA13) -> 2268 | AC13: =IF(AND(M13<>"", M13<>0), H13, "") -> A2 | AD13: =IF(AND(M13<>"", M13<>0), N13/$N$505*MATCH(AC13,'Misc Lists'!$K$2:$K$25,0), "") -> 1.3537024 | AE13: =IF(AND(M13<>"", M13<>0), I13, "") -> A- | AF13: =IF(AND(M13<>"", M13<>0), N13/$N$505*MATCH(AE13,'Misc Lists'!$L$2:$L$25,0), "") -> 1.5470885
B14: 91159XBG9 | C14: N/A | D14: US BANCORP SER CC MTN 5.20000% 12/26/2029 | E14: Corp | F14: 5.2 | G14: 47478 | H14: A3 | I14: A | J14: 100.332 | K14: 5.122 | L14: 40(2) | N14: =IF(AND(M14<>"", M14<>0), IF(L14 <> "N/A", IF(M14>=VALUE(LEFT(L14, FIND("(", L14)-1)), J14*10*M14, 1000*M14), 1000*M14), "") | O14: =IF(AND(M14<>"",M14<>0),N14/$N$505, "") | P14: =IF(AND(M14<>"", M14<>0), F14*1000/100, "") | Q14: =IF(AND(M14<>"", M14<>0), NOW(), "") | R14: =IF(AND(M14<>"", M14<>0), ROUND((G14 - Q14)/365, 0), "") | S14: =IF(AND(M14<>"",M14<>0),MDURATION(Q14,G14,F14/100,K14/100,2), "") | T14: =IF(AND(M14<>"",M14<>0),YIELD(Q14,G14,F14/100,N14/(M14*10),100,2),"") | U14: =IF(AND(M14<>"",M14<>0), IF(E14 = "Muni", T14, IF(E14="Corp", T14*(1 -'Investor Input'!$C$4-'Investor Input'!$C$5), T14*(1 -'Investor Input'!$C$4))), T14) | V14: =IF(AND(M14<>"",M14<>0),(FV(K14/(2*100),(G14-Q14)*2/365, F14*1000/(2*100), -N14/M14))*M14, "") | W14: =IF(AND(M14<>"",M14<>0),V14-N14,"") | X14: =IF(AND(M14<>"",M14<>0),W14/N14,"") | Y14: =IF(AND(M14<>"", M14<>0), MONTH(G14), "") | Z14: =IF(AND(M14<>"", M14<>0), MONTH(EDATE(G14, 6)), "") | AA14: =IF(AND(M14<>"", M14<>0), F14*1000*M14/(100*2), "") | AB14: =IF(AND(AA14<>"",AA14<>0), IF(E14="Muni", AA14, IF(E14 = "Corp", (1-'Investor Input'!$C$4-'Investor Input'!$C$5)*AA14, (1-'Investor Input'!$C$4)*AA14)), AA14) | AC14: =IF(AND(M14<>"", M14<>0), H14, "") | AD14: =IF(AND(M14<>"", M14<>0), N14/$N$505*MATCH(AC14,'Misc Lists'!$K$2:$K$25,0), "") | AE14: =IF(AND(M14<>"", M14<>0), I14, "") | AF14: =IF(AND(M14<>"", M14<>0), N14/$N$505*MATCH(AE14,'Misc Lists'!$L$2:$L$25,0), "")
B15: 06055JJV2 | C15: N/A | D15: BANK AMERICA CORP SER P MTN 5.20000% 02/26/2030 | E15: Corp | F15: 5.2 | G15: 47540 | H15: A1 | I15: A- | J15: 100.35 | K15: 5.119 | L15: 1,135(10) | N15: =IF(AND(M15<>"", M15<>0), IF(L15 <> "N/A", IF(M15>=VALUE(LEFT(L15, FIND("(", L15)-1)), J15*10*M15, 1000*M15), 1000*M15), "") | O15: =IF(AND(M15<>"",M15<>0),N15/$N$505, "") | P15: =IF(AND(M15<>"", M15<>0), F15*1000/100, "") | Q15: =IF(AND(M15<>"", M15<>0), NOW(), "") | R15: =IF(AND(M15<>"", M15<>0), ROUND((G15 - Q15)/365, 0), "") | S15: =IF(AND(M15<>"",M15<>0),MDURATION(Q15,G15,F15/100,K15/100,2), "") | T15: =IF(AND(M15<>"",M15<>0),YIELD(Q15,G15,F15/100,N15/(M15*10),100,2),"") | U15: =IF(AND(M15<>"",M15<>0), IF(E15 = "Muni", T15, IF(E15="Corp", T15*(1 -'Investor Input'!$C$4-'Investor Input'!$C$5), T15*(1 -'Investor Input'!$C$4))), T15) | V15: =IF(AND(M15<>"",M15<>0),(FV(K15/(2*100),(G15-Q15)*2/365, F15*1000/(2*100), -N15/M15))*M15, "") | W15: =IF(AND(M15<>"",M15<>0),V15-N15,"") | X15: =IF(AND(M15<>"",M15<>0),W15/N15,"") | Y15: =IF(AND(M15<>"", M15<>0), MONTH(G15), "") | Z15: =IF(AND(M15<>"", M15<>0), MONTH(EDATE(G15, 6)), "") | AA15: =IF(AND(M15<>"", M15<>0), F15*1000*M15/(100*2), "") | AB15: =IF(AND(AA15<>"",AA15<>0), IF(E15="Muni", AA15, IF(E15 = "Corp", (1-'Investor Input'!$C$4-'Investor Input'!$C$5)*AA15, (1-'Investor Input'!$C$4)*AA15)), AA15) | AC15: =IF(AND(M15<>"", M15<>0), H15, "") | AD15: =IF(AND(M15<>"", M15<>0), N15/$N$505*MATCH(AC15,'Misc Lists'!$K$2:$K$25,0), "") | AE15: =IF(AND(M15<>"", M15<>0), I15, "") | AF15: =IF(AND(M15<>"", M15<>0), N15/$N$505*MATCH(AE15,'Misc Lists'!$L$2:$L$25,0), "")
B16: 89788KAA4 | C16: N/A | D16: TRUIST BK NOTE 2.25000% 03/11/2030 | E16: Corp | F16: 2.25 | G16: 47553 | H16: A3 | I16: A- | J16: 87.493 | K16: 5.118 | L16: 500(250) | M16: 500 | N16: =IF(AND(M16<>"", M16<>0), IF(L16 <> "N/A", IF(M16>=VALUE(LEFT(L16, FIND("(", L16)-1)), J16*10*M16, 1000*M16), 1000*M16), "") -> 437465 | O16: =IF(AND(M16<>"",M16<>0),N16/$N$505, "") -> 0.43744704 | P16: =IF(AND(M16<>"", M16<>0), F16*1000/100, "") -> 22.5 | Q16: =IF(AND(M16<>"", M16<>0), NOW(), "") -> 45791.491 | R16: =IF(AND(M16<>"", M16<>0), ROUND((G16 - Q16)/365, 0), "") -> 5 | S16: =IF(AND(M16<>"",M16<>0),MDURATION(Q16,G16,F16/100,K16/100,2), "") -> 4.4470674 | T16: =IF(AND(M16<>"",M16<>0),YIELD(Q16,G16,F16/100,N16/(M16*10),100,2),"") -> 0.052145699 | U16: =IF(AND(M16<>"",M16<>0), IF(E16 = "Muni", T16, IF(E16="Corp", T16*(1 -'Investor Input'!$C$4-'Investor Input'!$C$5), T16*(1 -'Investor Input'!$C$4))), T16) -> 0.028158677 | V16: =IF(AND(M16<>"",M16<>0),(FV(K16/(2*100),(G16-Q16)*2/365, F16*1000/(2*100), -N16/M16))*M16, "") -> 497581.46 | W16: =IF(AND(M16<>"",M16<>0),V16-N16,"") -> 60116.461 | X16: =IF(AND(M16<>"",M16<>0),W16/N16,"") -> 0.13742005 | Y16: =IF(AND(M16<>"", M16<>0), MONTH(G16), "") -> 3 | Z16: =IF(AND(M16<>"", M16<>0), MONTH(EDATE(G16, 6)), "") -> 9 | AA16: =IF(AND(M16<>"", M16<>0), F16*1000*M16/(100*2), "") -> 5625 | AB16: =IF(AND(AA16<>"",AA16<>0), IF(E16="Muni", AA16, IF(E16 = "Corp", (1-'Investor Input'!$C$4-'Investor Input'!$C$5)*AA16, (1-'Investor Input'!$C$4)*AA16)), AA16) -> 3037.5 | AC16: =IF(AND(M16<>"", M16<>0), H16, "") -> A3 | AD16: =IF(AND(M16<>"", M16<>0), N16/$N$505*MATCH(AC16,'Misc Lists'!$K$2:$K$25,0), "") -> 3.4995763 | AE16: =IF(AND(M16<>"", M16<>0), I16, "") -> A- | AF16: =IF(AND(M16<>"", M16<>0), N16/$N$505*MATCH(AE16,'Misc Lists'!$L$2:$L$25,0), "") -> 3.4995763
B17: 46513JXM8 | C17: N/A | D17: ISRAEL(STATE OF) NOTE 2.50000% 01/15/2030 ISIN #US46513JXM88 SEDOL #BKVGCR7 | E17: Corp | F17: 2.5 | G17: 47498 | H17: BAA1 | I17: A | J17: 88.939 | K17: 5.107 | L17: 225(200) | N17: =IF(AND(M17<>"", M17<>0), IF(L17 <> "N/A", IF(M17>=VALUE(LEFT(L17, FIND("(", L17)-1)), J17*10*M17, 1000*M17), 1000*M17), "") | O17: =IF(AND(M17<>"",M17<>0),N17/$N$505, "") | P17: =IF(AND(M17<>"", M17<>0), F17*1000/100, "") | Q17: =IF(AND(M17<>"", M17<>0), NOW(), "") | R17: =IF(AND(M17<>"", M17<>0), ROUND((G17 - Q17)/365, 0), "") | S17: =IF(AND(M17<>"",M17<>0),MDURATION(Q17,G17,F17/100,K17/100,2), "") | T17: =IF(AND(M17<>"",M17<>0),YIELD(Q17,G17,F17/100,N17/(M17*10),100,2),"") | U17: =IF(AND(M17<>"",M17<>0), IF(E17 = "Muni", T17, IF(E17="Corp", T17*(1 -'Investor Input'!$C$4-'Investor Input'!$C$5), T17*(1 -'Investor Input'!$C$4))), T17) | V17: =IF(AND(M17<>"",M17<>0),(FV(K17/(2*100),(G17-Q17)*2/365, F17*1000/(2*100), -N17/M17))*M17, "") | W17: =IF(AND(M17<>"",M17<>0),V17-N17,"") | X17: =IF(AND(M17<>"",M17<>0),W17/N17,"") | Y17: =IF(AND(M17<>"", M17<>0), MONTH(G17), "") | Z17: =IF(AND(M17<>"", M17<>0), MONTH(EDATE(G17, 6)), "") | AA17: =IF(AND(M17<>"", M17<>0), F17*1000*M17/(100*2), "") | AB17: =IF(AND(AA17<>"",AA17<>0), IF(E17="Muni", AA17, IF(E17 = "Corp", (1-'Investor Input'!$C$4-'Investor Input'!$C$5)*AA17, (1-'Investor Input'!$C$4)*AA17)), AA17) | AC17: =IF(AND(M17<>"", M17<>0), H17, "") | AD17: =IF(AND(M17<>"", M17<>0), N17/$N$505*MATCH(AC17,'Misc Lists'!$K$2:$K$25,0), "") | AE17: =IF(AND(M17<>"", M17<>0), I17, "") | AF17: =IF(AND(M17<>"", M17<>0), N17/$N$505*MATCH(AE17,'Misc Lists'!$L$2:$L$25,0), "")
B18: 48135NTR7 | C18: N/A | D18: JPMORGAN CHASE FINL CO LLC SER A MTN 5.25000% 02/28/2030 | E18: Corp | F18: 5.25 | G18: 47542 | H18: A1 | I18: A | J18: 100.648 | K18: 5.1 | L18: 628(1) | N18: =IF(AND(M18<>"", M18<>0), IF(L18 <> "N/A", IF(M18>=VALUE(LEFT(L18, FIND("(", L18)-1)), J18*10*M18, 1000*M18), 1000*M18), "") | O18: =IF(AND(M18<>"",M18<>0),N18/$N$505, "") | P18: =IF(AND(M18<>"", M18<>0), F18*1000/100, "") | Q18: =IF(AND(M18<>"", M18<>0), NOW(), "") | R18: =IF(AND(M18<>"", M18<>0), ROUND((G18 - Q18)/365, 0), "") | S18: =IF(AND(M18<>"",M18<>0),MDURATION(Q18,G18,F18/100,K18/100,2), "") | T18: =IF(AND(M18<>"",M18<>0),YIELD(Q18,G18,F18/100,N18/(M18*10),100,2),"") | U18: =IF(AND(M18<>"",M18<>0), IF(E18 = "Muni", T18, IF(E18="Corp", T18*(1 -'Investor Input'!$C$4-'Investor Input'!$C$5), T18*(1 -'Investor Input'!$C$4))), T18) | V18: =IF(AND(M18<>"",M18<>0),(FV(K18/(2*100),(G18-Q18)*2/365, F18*1000/(2*100), -N18/M18))*M18, "") | W18: =IF(AND(M18<>"",M18<>0),V18-N18,"") | X18: =IF(AND(M18<>"",M18<>0),W18/N18,"") | Y18: =IF(AND(M18<>"", M18<>0), MONTH(G18), "") | Z18: =IF(AND(M18<>"", M18<>0), MONTH(EDATE(G18, 6)), "") | AA18: =IF(AND(M18<>"", M18<>0), F18*1000*M18/(100*2), "") | AB18: =IF(AND(AA18<>"",AA18<>0), IF(E18="Muni", AA18, IF(E18 = "Corp", (1-'Investor Input'!$C$4-'Investor Input'!$C$5)*AA18, (1-'Investor Input'!$C$4)*AA18)), AA18) | AC18: =IF(AND(M18<>"", M18<>0), H18, "") | AD18: =IF(AND(M18<>"", M18<>0), N18/$N$505*MATCH(AC18,'Misc Lists'!$K$2:$K$25,0), "") | AE18: =IF(AND(M18<>"", M18<>0), I18, "") | AF18: =IF(AND(M18<>"", M18<>0), N18/$N$505*MATCH(AE18,'Misc Lists'!$L$2:$L$25,0), "")
B19: 842400JC8 | C19: N/A | D19: SOUTHERN CALIF EDISON CO SER 2024D 5.15000% 06/01/2029 BOND CALL MAKE WHOLE | E19: Corp | F19: 5.15 | G19: 47270 | H19: A2 | I19: A- | J19: 100.205 | K19: 5.093 | L19: 100(10) | M19: 100 | N19: =IF(AND(M19<>"", M19<>0), IF(L19 <> "N/A", IF(M19>=VALUE(LEFT(L19, FIND("(", L19)-1)), J19*10*M19, 1000*M19), 1000*M19), "") -> 100205 | O19: =IF(AND(M19<>"",M19<>0),N19/$N$505, "") -> 0.10020089 | P19: =IF(AND(M19<>"", M19<>0), F19*1000/100, "") -> 51.5 | Q19: =IF(AND(M19<>"", M19<>0), NOW(), "") -> 45791.491 | R19: =IF(AND(M19<>"", M19<>0), ROUND((G19 - Q19)/365, 0), "") -> 4 | S19: =IF(AND(M19<>"",M19<>0),MDURATION(Q19,G19,F19/100,K19/100,2), "") -> 3.5315054 | T19: =IF(AND(M19<>"",M19<>0),YIELD(Q19,G19,F19/100,N19/(M19*10),100,2),"") -> 0.050925408 | U19: =IF(AND(M19<>"",M19<>0), IF(E19 = "Muni", T19, IF(E19="Corp", T19*(1 -'Investor Input'!$C$4-'Investor Input'!$C$5), T19*(1 -'Investor Input'!$C$4))), T19) -> 0.02749972 | V19: =IF(AND(M19<>"",M19<>0),(FV(K19/(2*100),(G19-Q19)*2/365, F19*1000/(2*100), -N19/M19))*M19, "") -> 99998.436 | W19: =IF(AND(M19<>"",M19<>0),V19-N19,"") -> -206.56367 | X19: =IF(AND(M19<>"",M19<>0),W19/N19,"") -> -0.0020614108 | Y19: =IF(AND(M19<>"", M19<>0), MONTH(G19), "") -> 6 | Z19: =IF(AND(M19<>"", M19<>0), MONTH(EDATE(G19, 6)), "") -> 12 | AA19: =IF(AND(M19<>"", M19<>0), F19*1000*M19/(100*2), "") -> 2575 | AB19: =IF(AND(AA19<>"",AA19<>0), IF(E19="Muni", AA19, IF(E19 = "Corp", (1-'Investor Input'!$C$4-'Investor Input'!$C$5)*AA19, (1-'Investor Input'!$C$4)*AA19)), AA19) -> 1390.5 | AC19: =IF(AND(M19<>"", M19<>0), H19, "") -> A2 | AD19: =IF(AND(M19<>"", M19<>0), N19/$N$505*MATCH(AC19,'Misc Lists'!$K$2:$K$25,0), "") -> 0.70140621 | AE19: =IF(AND(M19<>"", M19<>0), I19, "") -> A- | AF19: =IF(AND(M19<>"", M19<>0), N19/$N$505*MATCH(AE19,'Misc Lists'!$L$2:$L$25,0), "") -> 0.80160709
B20: 06055JJQ3 | C20: N/A | D20: BANK AMERICA CORP SER P MTN 5.15000% 02/06/2030 | E20: Corp | F20: 5.15 | G20: 47520 | H20: A1 | I20: A- | J20: 100.25 | K20: 5.092 | L20: 35(5) | N20: =IF(AND(M20<>"", M20<>0), IF(L20 <> "N/A", IF(M20>=VALUE(LEFT(L20, FIND("(", L20)-1)), J20*10*M20, 1000*M20), 1000*M20), "") | O20: =IF(AND(M20<>"",M20<>0),N20/$N$505, "") | P20: =IF(AND(M20<>"", M20<>0), F20*1000/100, "") | Q20: =IF(AND(M20<>"", M20<>0), NOW(), "") | R20: =IF(AND(M20<>"", M20<>0), ROUND((G20 - Q20)/365, 0), "") | S20: =IF(AND(M20<>"",M20<>0),MDURATION(Q20,G20,F20/100,K20/100,2), "") | T20: =IF(AND(M20<>"",M20<>0),YIELD(Q20,G20,F20/100,N20/(M20*10),100,2),"") | U20: =IF(AND(M20<>"",M20<>0), IF(E20 = "Muni", T20, IF(E20="Corp", T20*(1 -'Investor Input'!$C$4-'Investor Input'!$C$5), T20*(1 -'Investor Input'!$C$4))), T20) | V20: =IF(AND(M20<>"",M20<>0),(FV(K20/(2*100),(G20-Q20)*2/365, F20*1000/(2*100), -N20/M20))*M20, "") | W20: =IF(AND(M20<>"",M20<>0),V20-N20,"") | X20: =IF(AND(M20<>"",M20<>0),W20/N20,"") | Y20: =IF(AND(M20<>"", M20<>0), MONTH(G20), "") | Z20: =IF(AND(M20<>"", M20<>0), MONTH(EDATE(G20, 6)), "") | AA20: =IF(AND(M20<>"", M20<>0), F20*1000*M20/(100*2), "") | AB20: =IF(AND(AA20<>"",AA20<>0), IF(E20="Muni", AA20, IF(E20 = "Corp", (1-'Investor Input'!$C$4-'Investor Input'!$C$5)*AA20, (1-'Investor Input'!$C$4)*AA20)), AA20) | AC20: =IF(AND(M20<>"", M20<>0), H20, "") | AD20: =IF(AND(M20<>"", M20<>0), N20/$N$505*MATCH(AC20,'Misc Lists'!$K$2:$K$25,0), "") | AE20: =IF(AND(M20<>"", M20<>0), I20, "") | AF20: =IF(AND(M20<>"", M20<>0), N20/$N$505*MATCH(AE20,'Misc Lists'!$L$2:$L$25,0), "")
B21: 842400GS6 | C21: N/A | D21: SOUTHERN CALIF EDISON CO SER 2019C 2.85000% 08/01/2029 BOND CALL MAKE WHOLE | E21: Corp | F21: 2.85 | G21: 47331 | H21: A2 | I21: A- | J21: 91.299 | K21: 5.088 | L21: 500(1) | N21: =IF(AND(M21<>"", M21<>0), IF(L21 <> "N/A", IF(M21>=VALUE(LEFT(L21, FIND("(", L21)-1)), J21*10*M21, 1000*M21), 1000*M21), "") | O21: =IF(AND(M21<>"",M21<>0),N21/$N$505, "") | P21: =IF(AND(M21<>"", M21<>0), F21*1000/100, "") | Q21: =IF(AND(M21<>"", M21<>0), NOW(), "") | R21: =IF(AND(M21<>"", M21<>0), ROUND((G21 - Q21)/365, 0), "") | S21: =IF(AND(M21<>"",M21<>0),MDURATION(Q21,G21,F21/100,K21/100,2), "") | T21: =IF(AND(M21<>"",M21<>0),YIELD(Q21,G21,F21/100,N21/(M21*10),100,2),"") | U21: =IF(AND(M21<>"",M21<>0), IF(E21 = "Muni", T21, IF(E21="Corp", T21*(1 -'Investor Input'!$C$4-'Investor Input'!$C$5), T21*(1 -'Investor Input'!$C$4))), T21) | V21: =IF(AND(M21<>"",M21<>0),(FV(K21/(2*100),(G21-Q21)*2/365, F21*1000/(2*100), -N21/M21))*M21, "") | W21: =IF(AND(M21<>"",M21<>0),V21-N21,"") | X21: =IF(AND(M21<>"",M21<>0),W21/N21,"") | Y21: =IF(AND(M21<>"", M21<>0), MONTH(G21), "") | Z21: =IF(AND(M21<>"", M21<>0), MONTH(EDATE(G21, 6)), "") | AA21: =IF(AND(M21<>"", M21<>0), F21*1000*M21/(100*2), "") | AB21: =IF(AND(AA21<>"",AA21<>0), IF(E21="Muni", AA21, IF(E21 = "Corp", (1-'Investor Input'!$C$4-'Investor Input'!$C$5)*AA21, (1-'Investor Input'!$C$4)*AA21)), AA21) | AC21: =IF(AND(M21<>"", M21<>0), H21, "") | AD21: =IF(AND(M21<>"", M21<>0), N21/$N$505*MATCH(AC21,'Misc Lists'!$K$2:$K$25,0), "") | AE21: =IF(AND(M21<>"", M21<>0), I21, "") | AF21: =IF(AND(M21<>"", M21<>0), N21/$N$505*MATCH(AE21,'Misc Lists'!$L$2:$L$25,0), "")
B22: 06746AN33 | C22: N/A | D22: BARCLAYS BANK PLC SER A MTN 5.20000% 03/04/2030 | E22: Corp | F22: 5.2 | G22: 47546 | H22: A1 | I22: A+ | J22: 100.5 | K22: 5.085 | L22: 169(1) | N22: =IF(AND(M22<>"", M22<>0), IF(L22 <> "N/A", IF(M22>=VALUE(LEFT(L22, FIND("(", L22)-1)), J22*10*M22, 1000*M22), 1000*M22), "") | O22: =IF(AND(M22<>"",M22<>0),N22/$N$505, "") | P22: =IF(AND(M22<>"", M22<>0), F22*1000/100, "") | Q22: =IF(AND(M22<>"", M22<>0), NOW(), "") | R22: =IF(AND(M22<>"", M22<>0), ROUND((G22 - Q22)/365, 0), "") | S22: =IF(AND(M22<>"",M22<>0),MDURATION(Q22,G22,F22/100,K22/100,2), "") | T22: =IF(AND(M22<>"",M22<>0),YIELD(Q22,G22,F22/100,N22/(M22*10),100,2),"") | U22: =IF(AND(M22<>"",M22<>0), IF(E22 = "Muni", T22, IF(E22="Corp", T22*(1 -'Investor Input'!$C$4-'Investor Input'!$C$5), T22*(1 -'Investor Input'!$C$4))), T22) | V22: =IF(AND(M22<>"",M22<>0),(FV(K22/(2*100),(G22-Q22)*2/365, F22*1000/(2*100), -N22/M22))*M22, "") | W22: =IF(AND(M22<>"",M22<>0),V22-N22,"") | X22: =IF(AND(M22<>"",M22<>0),W22/N22,"") | Y22: =IF(AND(M22<>"", M22<>0), MONTH(G22), "") | Z22: =IF(AND(M22<>"", M22<>0), MONTH(EDATE(G22, 6)), "") | AA22: =IF(AND(M22<>"", M22<>0), F22*1000*M22/(100*2), "") | AB22: =IF(AND(AA22<>"",AA22<>0), IF(E22="Muni", AA22, IF(E22 = "Corp", (1-'Investor Input'!$C$4-'Investor Input'!$C$5)*AA22, (1-'Investor Input'!$C$4)*AA22)), AA22) | AC22: =IF(AND(M22<>"", M22<>0), H22, "") | AD22: =IF(AND(M22<>"", M22<>0), N22/$N$505*MATCH(AC22,'Misc Lists'!$K$2:$K$25,0), "") | AE22: =IF(AND(M22<>"", M22<>0), I22, "") | AF22: =IF(AND(M22<>"", M22<>0), N22/$N$505*MATCH(AE22,'Misc Lists'!$L$2:$L$25,0), "")
B23: 03076CAK2 | C23: N/A | D23: AMERIPRISE FINL INC NOTE 3.00000% 04/02/2025 | E23: Corp | F23: 3 | G23: 45749 | H23: A3 | I23: A- | J23: 99.882 | K23: 5.062 | L23: 250(10) | N23: =IF(AND(M23<>"", M23<>0), IF(L23 <> "N/A", IF(M23>=VALUE(LEFT(L23, FIND("(", L23)-1)), J23*10*M23, 1000*M23), 1000*M23), "") | O23: =IF(AND(M23<>"",M23<>0),N23/$N$505, "") | P23: =IF(AND(M23<>"", M23<>0), F23*1000/100, "") | Q23: =IF(AND(M23<>"", M23<>0), NOW(), "") | R23: =IF(AND(M23<>"", M23<>0), ROUND((G23 - Q23)/365, 0), "") | S23: =IF(AND(M23<>"",M23<>0),MDURATION(Q23,G23,F23/100,K23/100,2), "") | T23: =IF(AND(M23<>"",M23<>0),YIELD(Q23,G23,F23/100,N23/(M23*10),100,2),"") | U23: =IF(AND(M23<>"",M23<>0), IF(E23 = "Muni", T23, IF(E23="Corp", T23*(1 -'Investor Input'!$C$4-'Investor Input'!$C$5), T23*(1 -'Investor Input'!$C$4))), T23) | V23: =IF(AND(M23<>"",M23<>0),(FV(K23/(2*100),(G23-Q23)*2/365, F23*1000/(2*100), -N23/M23))*M23, "") | W23: =IF(AND(M23<>"",M23<>0),V23-N23,"") | X23: =IF(AND(M23<>"",M23<>0),W23/N23,"") | Y23: =IF(AND(M23<>"", M23<>0), MONTH(G23), "") | Z23: =IF(AND(M23<>"", M23<>0), MONTH(EDATE(G23, 6)), "") | AA23: =IF(AND(M23<>"", M23<>0), F23*1000*M23/(100*2), "") | AB23: =IF(AND(AA23<>"",AA23<>0), IF(E23="Muni", AA23, IF(E23 = "Corp", (1-'Investor Input'!$C$4-'Investor Input'!$C$5)*AA23, (1-'Investor Input'!$C$4)*AA23)), AA23) | AC23: =IF(AND(M23<>"", M23<>0), H23, "") | AD23: =IF(AND(M23<>"", M23<>0), N23/$N$505*MATCH(AC23,'Misc Lists'!$K$2:$K$25,0), "") | AE23: =IF(AND(M23<>"", M23<>0), I23, "") | AF23: =IF(AND(M23<>"", M23<>0), N23/$N$505*MATCH(AE23,'Misc Lists'!$L$2:$L$25,0), "")
B24: 25161FA99 | C24: N/A | D24: DEUTSCHE BK AG SER E NOTE 5.05000% 08/16/2029 | E24: Corp | F24: 5.05 | G24: 47346 | H24: A1 | I24: A | J24: 99.992 | K24: 5.051 | L24: 20(20) | M24: 20 | N24: =IF(AND(M24<>"", M24<>0), IF(L24 <> "N/A", IF(M24>=VALUE(LEFT(L24, FIND("(", L24)-1)), J24*10*M24, 1000*M24), 1000*M24), "") -> 19998.4 | O24: =IF(AND(M24<>"",M24<>0),N24/$N$505, "") -> 0.019997579 | P24: =IF(AND(M24<>"", M24<>0), F24*1000/100, "") -> 50.5 | Q24: =IF(AND(M24<>"", M24<>0), NOW(), "") -> 45791.491 | R24: =IF(AND(M24<>"", M24<>0), ROUND((G24 - Q24)/365, 0), "") -> 4 | S24: =IF(AND(M24<>"",M24<>0),MDURATION(Q24,G24,F24/100,K24/100,2), "") -> 3.7422842 | T24: =IF(AND(M24<>"",M24<>0),YIELD(Q24,G24,F24/100,N24/(M24*10),100,2),"") -> 0.050500354 | U24: =IF(AND(M24<>"",M24<>0), IF(E24 = "Muni", T24, IF(E24="Corp", T24*(1 -'Investor Input'!$C$4-'Investor Input'!$C$5), T24*(1 -'Investor Input'!$C$4))), T24) -> 0.027270191 | V24: =IF(AND(M24<>"",M24<>0),(FV(K24/(2*100),(G24-Q24)*2/365, F24*1000/(2*100), -N24/M24))*M24, "") -> 19998.959 | W24: =IF(AND(M24<>"",M24<>0),V24-N24,"") -> 0.55852125 | X24: =IF(AND(M24<>"",M24<>0),W24/N24,"") -> 2.7928297e-05 | Y24: =IF(AND(M24<>"", M24<>0), MONTH(G24), "") -> 8 | Z24: =IF(AND(M24<>"", M24<>0), MONTH(EDATE(G24, 6)), "") -> 2 | AA24: =IF(AND(M24<>"", M24<>0), F24*1000*M24/(100*2), "") -> 505 | AB24: =IF(AND(AA24<>"",AA24<>0), IF(E24="Muni", AA24, IF(E24 = "Corp", (1-'Investor Input'!$C$4-'Investor Input'!$C$5)*AA24, (1-'Investor Input'!$C$4)*AA24)), AA24) -> 272.7 | AC24: =IF(AND(M24<>"", M24<>0), H24, "") -> A1 | AD24: =IF(AND(M24<>"", M24<>0), N24/$N$505*MATCH(AC24,'Misc Lists'!$K$2:$K$25,0), "") -> 0.11998547 | AE24: =IF(AND(M24<>"", M24<>0), I24, "") -> A | AF24: =IF(AND(M24<>"", M24<>0), N24/$N$505*MATCH(AE24,'Misc Lists'!$L$2:$L$25,0), "") -> 0.13998305
B25: 48135NTG1 | C25: N/A | D25: JPMORGAN CHASE FINL CO LLC SER A MTN 5.15000% 02/14/2030 | E25: Corp | F25: 5.15 | G25: 47528 | H25: A1 | I25: A | J25: 100.442 | K25: 5.046 | L25: 980(1) | N25: =IF(AND(M25<>"", M25<>0), IF(L25 <> "N/A", IF(M25>=VALUE(LEFT(L25, FIND("(", L25)-1)), J25*10*M25, 1000*M25), 1000*M25), "") | O25: =IF(AND(M25<>"",M25<>0),N25/$N$505, "") | P25: =IF(AND(M25<>"", M25<>0), F25*1000/100, "") | Q25: =IF(AND(M25<>"", M25<>0), NOW(), "") | R25: =IF(AND(M25<>"", M25<>0), ROUND((G25 - Q25)/365, 0), "") | S25: =IF(AND(M25<>"",M25<>0),MDURATION(Q25,G25,F25/100,K25/100,2), "") | T25: =IF(AND(M25<>"",M25<>0),YIELD(Q25,G25,F25/100,N25/(M25*10),100,2),"") | U25: =IF(AND(M25<>"",M25<>0), IF(E25 = "Muni", T25, IF(E25="Corp", T25*(1 -'Investor Input'!$C$4-'Investor Input'!$C$5), T25*(1 -'Investor Input'!$C$4))), T25) | V25: =IF(AND(M25<>"",M25<>0),(FV(K25/(2*100),(G25-Q25)*2/365, F25*1000/(2*100), -N25/M25))*M25, "") | W25: =IF(AND(M25<>"",M25<>0),V25-N25,"") | X25: =IF(AND(M25<>"",M25<>0),W25/N25,"") | Y25: =IF(AND(M25<>"", M25<>0), MONTH(G25), "") | Z25: =IF(AND(M25<>"", M25<>0), MONTH(EDATE(G25, 6)), "") | AA25: =IF(AND(M25<>"", M25<>0), F25*1000*M25/(100*2), "") | AB25: =IF(AND(AA25<>"",AA25<>0), IF(E25="Muni", AA25, IF(E25 = "Corp", (1-'Investor Input'!$C$4-'Investor Input'!$C$5)*AA25, (1-'Investor Input'!$C$4)*AA25)), AA25) | AC25: =IF(AND(M25<>"", M25<>0), H25, "") | AD25: =IF(AND(M25<>"", M25<>0), N25/$N$505*MATCH(AC25,'Misc Lists'!$K$2:$K$25,0), "") | AE25: =IF(AND(M25<>"", M25<>0), I25, "") | AF25: =IF(AND(M25<>"", M25<>0), N25/$N$505*MATCH(AE25,'Misc Lists'!$L$2:$L$25,0), "")
B26: 89114XDV2 | C26: N/A | D26: TORONTO DOMINION BK ONT SER D MTN 5.10000% 02/15/2027 ISIN #US89114XDV29 | E26: Corp | F26: 5.1 | G26: 46433 | H26: A2 | I26: A- | J26: 100.115 | K26: 5.036 | L26: 75(25) | N26: =IF(AND(M26<>"", M26<>0), IF(L26 <> "N/A", IF(M26>=VALUE(LEFT(L26, FIND("(", L26)-1)), J26*10*M26, 1000*M26), 1000*M26), "") | O26: =IF(AND(M26<>"",M26<>0),N26/$N$505, "") | P26: =IF(AND(M26<>"", M26<>0), F26*1000/100, "") | Q26: =IF(AND(M26<>"", M26<>0), NOW(), "") | R26: =IF(AND(M26<>"", M26<>0), ROUND((G26 - Q26)/365, 0), "") | S26: =IF(AND(M26<>"",M26<>0),MDURATION(Q26,G26,F26/100,K26/100,2), "") | T26: =IF(AND(M26<>"",M26<>0),YIELD(Q26,G26,F26/100,N26/(M26*10),100,2),"") | U26: =IF(AND(M26<>"",M26<>0), IF(E26 = "Muni", T26, IF(E26="Corp", T26*(1 -'Investor Input'!$C$4-'Investor Input'!$C$5), T26*(1 -'Investor Input'!$C$4))), T26) | V26: =IF(AND(M26<>"",M26<>0),(FV(K26/(2*100),(G26-Q26)*2/365, F26*1000/(2*100), -N26/M26))*M26, "") | W26: =IF(AND(M26<>"",M26<>0),V26-N26,"") | X26: =IF(AND(M26<>"",M26<>0),W26/N26,"") | Y26: =IF(AND(M26<>"", M26<>0), MONTH(G26), "") | Z26: =IF(AND(M26<>"", M26<>0), MONTH(EDATE(G26, 6)), "") | AA26: =IF(AND(M26<>"", M26<>0), F26*1000*M26/(100*2), "") | AB26: =IF(AND(AA26<>"",AA26<>0), IF(E26="Muni", AA26, IF(E26 = "Corp", (1-'Investor Input'!$C$4-'Investor Input'!$C$5)*AA26, (1-'Investor Input'!$C$4)*AA26)), AA26) | AC26: =IF(AND(M26<>"", M26<>0), H26, "") | AD26: =IF(AND(M26<>"", M26<>0), N26/$N$505*MATCH(AC26,'Misc Lists'!$K$2:$K$25,0), "") | AE26: =IF(AND(M26<>"", M26<>0), I26, "") | AF26: =IF(AND(M26<>"", M26<>0), N26/$N$505*MATCH(AE26,'Misc Lists'!$L$2:$L$25,0), "")
B27: 06418VKL7 | C27: N/A | D27: BANK NOVA SCOTIA B CSER B NOTE 5.05000% 02/28/2030 | E27: Corp | F27: 5.05 | G27: 47542 | H27: A2 | I27: A- | J27: 100.09 | K27: 5.029 | L27: 975(1) | N27: =IF(AND(M27<>"", M27<>0), IF(L27 <> "N/A", IF(M27>=VALUE(LEFT(L27, FIND("(", L27)-1)), J27*10*M27, 1000*M27), 1000*M27), "") | O27: =IF(AND(M27<>"",M27<>0),N27/$N$505, "") | P27: =IF(AND(M27<>"", M27<>0), F27*1000/100, "") | Q27: =IF(AND(M27<>"", M27<>0), NOW(), "") | R27: =IF(AND(M27<>"", M27<>0), ROUND((G27 - Q27)/365, 0), "") | S27: =IF(AND(M27<>"",M27<>0),MDURATION(Q27,G27,F27/100,K27/100,2), "") | T27: =IF(AND(M27<>"",M27<>0),YIELD(Q27,G27,F27/100,N27/(M27*10),100,2),"") | U27: =IF(AND(M27<>"",M27<>0), IF(E27 = "Muni", T27, IF(E27="Corp", T27*(1 -'Investor Input'!$C$4-'Investor Input'!$C$5), T27*(1 -'Investor Input'!$C$4))), T27) | V27: =IF(AND(M27<>"",M27<>0),(FV(K27/(2*100),(G27-Q27)*2/365, F27*1000/(2*100), -N27/M27))*M27, "") | W27: =IF(AND(M27<>"",M27<>0),V27-N27,"") | X27: =IF(AND(M27<>"",M27<>0),W27/N27,"") | Y27: =IF(AND(M27<>"", M27<>0), MONTH(G27), "") | Z27: =IF(AND(M27<>"", M27<>0), MONTH(EDATE(G27, 6)), "") | AA27: =IF(AND(M27<>"", M27<>0), F27*1000*M27/(100*2), "") | AB27: =IF(AND(AA27<>"",AA27<>0), IF(E27="Muni", AA27, IF(E27 = "Corp", (1-'Investor Input'!$C$4-'Investor Input'!$C$5)*AA27, (1-'Investor Input'!$C$4)*AA27)), AA27) | AC27: =IF(AND(M27<>"", M27<>0), H27, "") | AD27: =IF(AND(M27<>"", M27<>0), N27/$N$505*MATCH(AC27,'Misc Lists'!$K$2:$K$25,0), "") | AE27: =IF(AND(M27<>"", M27<>0), I27, "") | AF27: =IF(AND(M27<>"", M27<>0), N27/$N$505*MATCH(AE27,'Misc Lists'!$L$2:$L$25,0), "")
B28: 63305MDA6 | C28: N/A | D28: NATL BANK OF CANADA NOTE 5.00000% 08/28/2028 | E28: Corp | F28: 5 | G28: 46993 | H28: AA2 | I28: A+ | J28: 99.95 | K28: 5.023 | L28: 725(100) | N28: =IF(AND(M28<>"", M28<>0), IF(L28 <> "N/A", IF(M28>=VALUE(LEFT(L28, FIND("(", L28)-1)), J28*10*M28, 1000*M28), 1000*M28), "") | O28: =IF(AND(M28<>"",M28<>0),N28/$N$505, "") | P28: =IF(AND(M28<>"", M28<>0), F28*1000/100, "") | Q28: =IF(AND(M28<>"", M28<>0), NOW(), "") | R28: =IF(AND(M28<>"", M28<>0), ROUND((G28 - Q28)/365, 0), "") | S28: =IF(AND(M28<>"",M28<>0),MDURATION(Q28,G28,F28/100,K28/100,2), "") | T28: =IF(AND(M28<>"",M28<>0),YIELD(Q28,G28,F28/100,N28/(M28*10),100,2),"") | U28: =IF(AND(M28<>"",M28<>0), IF(E28 = "Muni", T28, IF(E28="Corp", T28*(1 -'Investor Input'!$C$4-'Investor Input'!$C$5), T28*(1 -'Investor Input'!$C$4))), T28) | V28: =IF(AND(M28<>"",M28<>0),(FV(K28/(2*100),(G28-Q28)*2/365, F28*1000/(2*100), -N28/M28))*M28, "") | W28: =IF(AND(M28<>"",M28<>0),V28-N28,"") | X28: =IF(AND(M28<>"",M28<>0),W28/N28,"") | Y28: =IF(AND(M28<>"", M28<>0), MONTH(G28), "") | Z28: =IF(AND(M28<>"", M28<>0), MONTH(EDATE(G28, 6)), "") | AA28: =IF(AND(M28<>"", M28<>0), F28*1000*M28/(100*2), "") | AB28: =IF(AND(AA28<>"",AA28<>0), IF(E28="Muni", AA28, IF(E28 = "Corp", (1-'Investor Input'!$C$4-'Investor Input'!$C$5)*AA28, (1-'Investor Input'!$C$4)*AA28)), AA28) | AC28: =IF(AND(M28<>"", M28<>0), H28, "") | AD28: =IF(AND(M28<>"", M28<>0), N28/$N$505*MATCH(AC28,'Misc Lists'!$K$2:$K$25,0), "") | AE28: =IF(AND(M28<>"", M28<>0), I28, "") | AF28: =IF(AND(M28<>"", M28<>0), N28/$N$505*MATCH(AE28,'Misc Lists'!$L$2:$L$25,0), "")
B29: 854502AL5 | C29: N/A | D29: STANLEY BLACK &DECKER INC NOTE 2.30000% 03/15/2030 CALL MAKE WHOLE | E29: Corp | F29: 2.3 | G29: 47557 | H29: BAA3 | I29: A- | J29: 88.087 | K29: 5.02 | L29: 500(2) | N29: =IF(AND(M29<>"", M29<>0), IF(L29 <> "N/A", IF(M29>=VALUE(LEFT(L29, FIND("(", L29)-1)), J29*10*M29, 1000*M29), 1000*M29), "") | O29: =IF(AND(M29<>"",M29<>0),N29/$N$505, "") | P29: =IF(AND(M29<>"", M29<>0), F29*1000/100, "") | Q29: =IF(AND(M29<>"", M29<>0), NOW(), "") | R29: =IF(AND(M29<>"", M29<>0), ROUND((G29 - Q29)/365, 0), "") | S29: =IF(AND(M29<>"",M29<>0),MDURATION(Q29,G29,F29/100,K29/100,2), "") | T29: =IF(AND(M29<>"",M29<>0),YIELD(Q29,G29,F29/100,N29/(M29*10),100,2),"") | U29: =IF(AND(M29<>"",M29<>0), IF(E29 = "Muni", T29, IF(E29="Corp", T29*(1 -'Investor Input'!$C$4-'Investor Input'!$C$5), T29*(1 -'Investor Input'!$C$4))), T29) | V29: =IF(AND(M29<>"",M29<>0),(FV(K29/(2*100),(G29-Q29)*2/365, F29*1000/(2*100), -N29/M29))*M29, "") | W29: =IF(AND(M29<>"",M29<>0),V29-N29,"") | X29: =IF(AND(M29<>"",M29<>0),W29/N29,"") | Y29: =IF(AND(M29<>"", M29<>0), MONTH(G29), "") | Z29: =IF(AND(M29<>"", M29<>0), MONTH(EDATE(G29, 6)), "") | AA29: =IF(AND(M29<>"", M29<>0), F29*1000*M29/(100*2), "") | AB29: =IF(AND(AA29<>"",AA29<>0), IF(E29="Muni", AA29, IF(E29 = "Corp", (1-'Investor Input'!$C$4-'Investor Input'!$C$5)*AA29, (1-'Investor Input'!$C$4)*AA29)), AA29) | AC29: =IF(AND(M29<>"", M29<>0), H29, "") | AD29: =IF(AND(M29<>"", M29<>0), N29/$N$505*MATCH(AC29,'Misc Lists'!$K$2:$K$25,0), "") | AE29: =IF(AND(M29<>"", M29<>0), I29, "") | AF29: =IF(AND(M29<>"", M29<>0), N29/$N$505*MATCH(AE29,'Misc Lists'!$L$2:$L$25,0), "")
B30: 842400GJ6 | C30: N/A | D30: SOUTHERN CALIF EDISON CO SER 2018B 3.65000% 03/01/2028 BOND CALL MAKE WHOLE | E30: Corp | F30: 3.65 | G30: 46813 | H30: A2 | I30: A- | J30: 96.264 | K30: 5.019 | L30: 500(1) | N30: =IF(AND(M30<>"", M30<>0), IF(L30 <> "N/A", IF(M30>=VALUE(LEFT(L30, FIND("(", L30)-1)), J30*10*M30, 1000*M30), 1000*M30), "") | O30: =IF(AND(M30<>"",M30<>0),N30/$N$505, "") | P30: =IF(AND(M30<>"", M30<>0), F30*1000/100, "") | Q30: =IF(AND(M30<>"", M30<>0), NOW(), "") | R30: =IF(AND(M30<>"", M30<>0), ROUND((G30 - Q30)/365, 0), "") | S30: =IF(AND(M30<>"",M30<>0),MDURATION(Q30,G30,F30/100,K30/100,2), "") | T30: =IF(AND(M30<>"",M30<>0),YIELD(Q30,G30,F30/100,N30/(M30*10),100,2),"") | U30: =IF(AND(M30<>"",M30<>0), IF(E30 = "Muni", T30, IF(E30="Corp", T30*(1 -'Investor Input'!$C$4-'Investor Input'!$C$5), T30*(1 -'Investor Input'!$C$4))), T30) | V30: =IF(AND(M30<>"",M30<>0),(FV(K30/(2*100),(G30-Q30)*2/365, F30*1000/(2*100), -N30/M30))*M30, "") | W30: =IF(AND(M30<>"",M30<>0),V30-N30,"") | X30: =IF(AND(M30<>"",M30<>0),W30/N30,"") | Y30: =IF(AND(M30<>"", M30<>0), MONTH(G30), "") | Z30: =IF(AND(M30<>"", M30<>0), MONTH(EDATE(G30, 6)), "") | AA30: =IF(AND(M30<>"", M30<>0), F30*1000*M30/(100*2), "") | AB30: =IF(AND(AA30<>"",AA30<>0), IF(E30="Muni", AA30, IF(E30 = "Corp", (1-'Investor Input'!$C$4-'Investor Input'!$C$5)*AA30, (1-'Investor Input'!$C$4)*AA30)), AA30) | AC30: =IF(AND(M30<>"", M30<>0), H30, "") | AD30: =IF(AND(M30<>"", M30<>0), N30/$N$505*MATCH(AC30,'Misc Lists'!$K$2:$K$25,0), "") | AE30: =IF(AND(M30<>"", M30<>0), I30, "") | AF30: =IF(AND(M30<>"", M30<>0), N30/$N$505*MATCH(AE30,'Misc Lists'!$L$2:$L$25,0), "")
B31: 06418VHG2 | C31: N/A | D31: BANK NOVA SCOTIA B CSER B NOTE 5.10000% 02/14/2030 | E31: Corp | F31: 5.1 | G31: 47528 | H31: A2 | I31: A- | J31: 100.358 | K31: 5.016 | L31: 999(1) | N31: =IF(AND(M31<>"", M31<>0), IF(L31 <> "N/A", IF(M31>=VALUE(LEFT(L31, FIND("(", L31)-1)), J31*10*M31, 1000*M31), 1000*M31), "") | O31: =IF(AND(M31<>"",M31<>0),N31/$N$505, "") | P31: =IF(AND(M31<>"", M31<>0), F31*1000/100, "") | Q31: =IF(AND(M31<>"", M31<>0), NOW(), "") | R31: =IF(AND(M31<>"", M31<>0), ROUND((G31 - Q31)/365, 0), "") | S31: =IF(AND(M31<>"",M31<>0),MDURATION(Q31,G31,F31/100,K31/100,2), "") | T31: =IF(AND(M31<>"",M31<>0),YIELD(Q31,G31,F31/100,N31/(M31*10),100,2),"") | U31: =IF(AND(M31<>"",M31<>0), IF(E31 = "Muni", T31, IF(E31="Corp", T31*(1 -'Investor Input'!$C$4-'Investor Input'!$C$5), T31*(1 -'Investor Input'!$C$4))), T31) | V31: =IF(AND(M31<>"",M31<>0),(FV(K31/(2*100),(G31-Q31)*2/365, F31*1000/(2*100), -N31/M31))*M31, "") | W31: =IF(AND(M31<>"",M31<>0),V31-N31,"") | X31: =IF(AND(M31<>"",M31<>0),W31/N31,"") | Y31: =IF(AND(M31<>"", M31<>0), MONTH(G31), "") | Z31: =IF(AND(M31<>"", M31<>0), MONTH(EDATE(G31, 6)), "") | AA31: =IF(AND(M31<>"", M31<>0), F31*1000*M31/(100*2), "") | AB31: =IF(AND(AA31<>"",AA31<>0), IF(E31="Muni", AA31, IF(E31 = "Corp", (1-'Investor Input'!$C$4-'Investor Input'!$C$5)*AA31, (1-'Investor Input'!$C$4)*AA31)), AA31) | AC31: =IF(AND(M31<>"", M31<>0), H31, "") | AD31: =IF(AND(M31<>"", M31<>0), N31/$N$505*MATCH(AC31,'Misc Lists'!$K$2:$K$25,0), "") | AE31: =IF(AND(M31<>"", M31<>0), I31, "") | AF31: =IF(AND(M31<>"", M31<>0), N31/$N$505*MATCH(AE31,'Misc Lists'!$L$2:$L$25,0), "")
B32: 842400HU0 | C32: N/A | D32: SOUTHERN CALIF EDISON CO SER 2023A 5.30000% 03/01/2028 BOND CALL MAKE WHOLE | E32: Corp | F32: 5.3 | G32: 46813 | H32: A2 | I32: A- | J32: 100.778 | K32: 5.014 | L32: 500(1) | N32: =IF(AND(M32<>"", M32<>0), IF(L32 <> "N/A", IF(M32>=VALUE(LEFT(L32, FIND("(", L32)-1)), J32*10*M32, 1000*M32), 1000*M32), "") | O32: =IF(AND(M32<>"",M32<>0),N32/$N$505, "") | P32: =IF(AND(M32<>"", M32<>0), F32*1000/100, "") | Q32: =IF(AND(M32<>"", M32<>0), NOW(), "") | R32: =IF(AND(M32<>"", M32<>0), ROUND((G32 - Q32)/365, 0), "") | S32: =IF(AND(M32<>"",M32<>0),MDURATION(Q32,G32,F32/100,K32/100,2), "") | T32: =IF(AND(M32<>"",M32<>0),YIELD(Q32,G32,F32/100,N32/(M32*10),100,2),"") | U32: =IF(AND(M32<>"",M32<>0), IF(E32 = "Muni", T32, IF(E32="Corp", T32*(1 -'Investor Input'!$C$4-'Investor Input'!$C$5), T32*(1 -'Investor Input'!$C$4))), T32) | V32: =IF(AND(M32<>"",M32<>0),(FV(K32/(2*100),(G32-Q32)*2/365, F32*1000/(2*100), -N32/M32))*M32, "") | W32: =IF(AND(M32<>"",M32<>0),V32-N32,"") | X32: =IF(AND(M32<>"",M32<>0),W32/N32,"") | Y32: =IF(AND(M32<>"", M32<>0), MONTH(G32), "") | Z32: =IF(AND(M32<>"", M32<>0), MONTH(EDATE(G32, 6)), "") | AA32: =IF(AND(M32<>"", M32<>0), F32*1000*M32/(100*2), "") | AB32: =IF(AND(AA32<>"",AA32<>0), IF(E32="Muni", AA32, IF(E32 = "Corp", (1-'Investor Input'!$C$4-'Investor Input'!$C$5)*AA32, (1-'Investor Input'!$C$4)*AA32)), AA32) | AC32: =IF(AND(M32<>"", M32<>0), H32, "") | AD32: =IF(AND(M32<>"", M32<>0), N32/$N$505*MATCH(AC32,'Misc Lists'!$K$2:$K$25,0), "") | AE32: =IF(AND(M32<>"", M32<>0), I32, "") | AF32: =IF(AND(M32<>"", M32<>0), N32/$N$505*MATCH(AE32,'Misc Lists'!$L$2:$L$25,0), "")
B33: 756109BQ6 | C33: N/A | D33: REALTY INCOME CORP NOTE 5.05000% 01/13/2026 | E33: Corp | F33: 5.05 | G33: 46035 | H33: A3 | I33: A- | J33: 100.03 | K33: 5.004 | L33: 18(18) | N33: =IF(AND(M33<>"", M33<>0), IF(L33 <> "N/A", IF(M33>=VALUE(LEFT(L33, FIND("(", L33)-1)), J33*10*M33, 1000*M33), 1000*M33), "") | O33: =IF(AND(M33<>"",M33<>0),N33/$N$505, "") | P33: =IF(AND(M33<>"", M33<>0), F33*1000/100, "") | Q33: =IF(AND(M33<>"", M33<>0), NOW(), "") | R33: =IF(AND(M33<>"", M33<>0), ROUND((G33 - Q33)/365, 0), "") | S33: =IF(AND(M33<>"",M33<>0),MDURATION(Q33,G33,F33/100,K33/100,2), "") | T33: =IF(AND(M33<>"",M33<>0),YIELD(Q33,G33,F33/100,N33/(M33*10),100,2),"") | U33: =IF(AND(M33<>"",M33<>0), IF(E33 = "Muni", T33, IF(E33="Corp", T33*(1 -'Investor Input'!$C$4-'Investor Input'!$C$5), T33*(1 -'Investor Input'!$C$4))), T33) | V33: =IF(AND(M33<>"",M33<>0),(FV(K33/(2*100),(G33-Q33)*2/365, F33*1000/(2*100), -N33/M33))*M33, "") | W33: =IF(AND(M33<>"",M33<>0),V33-N33,"") | X33: =IF(AND(M33<>"",M33<>0),W33/N33,"") | Y33: =IF(AND(M33<>"", M33<>0), MONTH(G33), "") | Z33: =IF(AND(M33<>"", M33<>0), MONTH(EDATE(G33, 6)), "") | AA33: =IF(AND(M33<>"", M33<>0), F33*1000*M33/(100*2), "") | AB33: =IF(AND(AA33<>"",AA33<>0), IF(E33="Muni", AA33, IF(E33 = "Corp", (1-'Investor Input'!$C$4-'Investor Input'!$C$5)*AA33, (1-'Investor Input'!$C$4)*AA33)), AA33) | AC33: =IF(AND(M33<>"", M33<>0), H33, "") | AD33: =IF(AND(M33<>"", M33<>0), N33/$N$505*MATCH(AC33,'Misc Lists'!$K$2:$K$25,0), "") | AE33: =IF(AND(M33<>"", M33<>0), I33, "") | AF33: =IF(AND(M33<>"", M33<>0), N33/$N$505*MATCH(AE33,'Misc Lists'!$L$2:$L$25,0), "")
B34: 06376CHS8 | C34: N/A | D34: BANK MONTREAL MEDIUMSER I MTN 5.00000% 08/24/2028 | E34: Corp | F34: 5 | G34: 46989 | H34: A2 | I34: A- | J34: 99.99 | K34: 5.002 | L34: 940(1) | N34: =IF(AND(M34<>"", M34<>0), IF(L34 <> "N/A", IF(M34>=VALUE(LEFT(L34, FIND("(", L34)-1)), J34*10*M34, 1000*M34), 1000*M34), "") | O34: =IF(AND(M34<>"",M34<>0),N34/$N$505, "") | P34: =IF(AND(M34<>"", M34<>0), F34*1000/100, "") | Q34: =IF(AND(M34<>"", M34<>0), NOW(), "") | R34: =IF(AND(M34<>"", M34<>0), ROUND((G34 - Q34)/365, 0), "") | S34: =IF(AND(M34<>"",M34<>0),MDURATION(Q34,G34,F34/100,K34/100,2), "") | T34: =IF(AND(M34<>"",M34<>0),YIELD(Q34,G34,F34/100,N34/(M34*10),100,2),"") | U34: =IF(AND(M34<>"",M34<>0), IF(E34 = "Muni", T34, IF(E34="Corp", T34*(1 -'Investor Input'!$C$4-'Investor Input'!$C$5), T34*(1 -'Investor Input'!$C$4))), T34) | V34: =IF(AND(M34<>"",M34<>0),(FV(K34/(2*100),(G34-Q34)*2/365, F34*1000/(2*100), -N34/M34))*M34, "") | W34: =IF(AND(M34<>"",M34<>0),V34-N34,"") | X34: =IF(AND(M34<>"",M34<>0),W34/N34,"") | Y34: =IF(AND(M34<>"", M34<>0), MONTH(G34), "") | Z34: =IF(AND(M34<>"", M34<>0), MONTH(EDATE(G34, 6)), "") | AA34: =IF(AND(M34<>"", M34<>0), F34*1000*M34/(100*2), "") | AB34: =IF(AND(AA34<>"",AA34<>0), IF(E34="Muni", AA34, IF(E34 = "Corp", (1-'Investor Input'!$C$4-'Investor Input'!$C$5)*AA34, (1-'Investor Input'!$C$4)*AA34)), AA34) | AC34: =IF(AND(M34<>"", M34<>0), H34, "") | AD34: =IF(AND(M34<>"", M34<>0), N34/$N$505*MATCH(AC34,'Misc Lists'!$K$2:$K$25,0), "") | AE34: =IF(AND(M34<>"", M34<>0), I34, "") | AF34: =IF(AND(M34<>"", M34<>0), N34/$N$505*MATCH(AE34,'Misc Lists'!$L$2:$L$25,0), "")
B35: 05964HBJ3 | C35: N/A | D35: BANCO SANTANDER S.A.SER 241 NOTE 5.56500% 01/17/2030 | E35: Corp | F35: 5.565 | G35: 47500 | H35: BAA1 | I35: A- | J35: 102.396 | K35: 5.001 | L35: 500(200) | N35: =IF(AND(M35<>"", M35<>0), IF(L35 <> "N/A", IF(M35>=VALUE(LEFT(L35, FIND("(", L35)-1)), J35*10*M35, 1000*M35), 1000*M35), "") | O35: =IF(AND(M35<>"",M35<>0),N35/$N$505, "") | P35: =IF(AND(M35<>"", M35<>0), F35*1000/100, "") | Q35: =IF(AND(M35<>"", M35<>0), NOW(), "") | R35: =IF(AND(M35<>"", M35<>0), ROUND((G35 - Q35)/365, 0), "") | S35: =IF(AND(M35<>"",M35<>0),MDURATION(Q35,G35,F35/100,K35/100,2), "") | T35: =IF(AND(M35<>"",M35<>0),YIELD(Q35,G35,F35/100,N35/(M35*10),100,2),"") | U35: =IF(AND(M35<>"",M35<>0), IF(E35 = "Muni", T35, IF(E35="Corp", T35*(1 -'Investor Input'!$C$4-'Investor Input'!$C$5), T35*(1 -'Investor Input'!$C$4))), T35) | V35: =IF(AND(M35<>"",M35<>0),(FV(K35/(2*100),(G35-Q35)*2/365, F35*1000/(2*100), -N35/M35))*M35, "") | W35: =IF(AND(M35<>"",M35<>0),V35-N35,"") | X35: =IF(AND(M35<>"",M35<>0),W35/N35,"") | Y35: =IF(AND(M35<>"", M35<>0), MONTH(G35), "") | Z35: =IF(AND(M35<>"", M35<>0), MONTH(EDATE(G35, 6)), "") | AA35: =IF(AND(M35<>"", M35<>0), F35*1000*M35/(100*2), "") | AB35: =IF(AND(AA35<>"",AA35<>0), IF(E35="Muni", AA35, IF(E35 = "Corp", (1-'Investor Input'!$C$4-'Investor Input'!$C$5)*AA35, (1-'Investor Input'!$C$4)*AA35)), AA35) | AC35: =IF(AND(M35<>"", M35<>0), H35, "") | AD35: =IF(AND(M35<>"", M35<>0), N35/$N$505*MATCH(AC35,'Misc Lists'!$K$2:$K$25,0), "") | AE35: =IF(AND(M35<>"", M35<>0), I35, "") | AF35: =IF(AND(M35<>"", M35<>0), N35/$N$505*MATCH(AE35,'Misc Lists'!$L$2:$L$25,0), "")
B36: 842400HY2 | C36: N/A | D36: SOUTHERN CALIF EDISON CO SER 2023E 5.65000% 10/01/2028 BOND CALL MAKE WHOLE | E36: Corp | F36: 5.65 | G36: 47027 | H36: A2 | I36: A- | J36: 102.106 | K36: 4.995 | L36: 200(1) | N36: =IF(AND(M36<>"", M36<>0), IF(L36 <> "N/A", IF(M36>=VALUE(LEFT(L36, FIND("(", L36)-1)), J36*10*M36, 1000*M36), 1000*M36), "") | O36: =IF(AND(M36<>"",M36<>0),N36/$N$505, "") | P36: =IF(AND(M36<>"", M36<>0), F36*1000/100, "") | Q36: =IF(AND(M36<>"", M36<>0), NOW(), "") | R36: =IF(AND(M36<>"", M36<>0), ROUND((G36 - Q36)/365, 0), "") | S36: =IF(AND(M36<>"",M36<>0),MDURATION(Q36,G36,F36/100,K36/100,2), "") | T36: =IF(AND(M36<>"",M36<>0),YIELD(Q36,G36,F36/100,N36/(M36*10),100,2),"") | U36: =IF(AND(M36<>"",M36<>0), IF(E36 = "Muni", T36, IF(E36="Corp", T36*(1 -'Investor Input'!$C$4-'Investor Input'!$C$5), T36*(1 -'Investor Input'!$C$4))), T36) | V36: =IF(AND(M36<>"",M36<>0),(FV(K36/(2*100),(G36-Q36)*2/365, F36*1000/(2*100), -N36/M36))*M36, "") | W36: =IF(AND(M36<>"",M36<>0),V36-N36,"") | X36: =IF(AND(M36<>"",M36<>0),W36/N36,"") | Y36: =IF(AND(M36<>"", M36<>0), MONTH(G36), "") | Z36: =IF(AND(M36<>"", M36<>0), MONTH(EDATE(G36, 6)), "") | AA36: =IF(AND(M36<>"", M36<>0), F36*1000*M36/(100*2), "") | AB36: =IF(AND(AA36<>"",AA36<>0), IF(E36="Muni", AA36, IF(E36 = "Corp", (1-'Investor Input'!$C$4-'Investor Input'!$C$5)*AA36, (1-'Investor Input'!$C$4)*AA36)), AA36) | AC36: =IF(AND(M36<>"", M36<>0), H36, "") | AD36: =IF(AND(M36<>"", M36<>0), N36/$N$505*MATCH(AC36,'Misc Lists'!$K$2:$K$25,0), "") | AE36: =IF(AND(M36<>"", M36<>0), I36, "") | AF36: =IF(AND(M36<>"", M36<>0), N36/$N$505*MATCH(AE36,'Misc Lists'!$L$2:$L$25,0), "")
